2018-07-10 20:05:50,616 - all - INFO - views.py line:119-- timestamp : 1531224350295 
2018-07-10 20:21:43,862 - django.request - WARNING - base.py line:93-- Not Found: /admin 
2018-07-10 20:21:43,972 - django.request - ERROR - exception.py line:118-- Internal Server Error: /favicon.ico 
Traceback (most recent call last):
  File "E:\common\Python\lib\site-packages\django\core\handlers\exception.py", line 35, in inner
    response = get_response(request)
  File "E:\common\Python\lib\site-packages\django\utils\deprecation.py", line 93, in __call__
    response = self.process_request(request)
  File "E:\common\Python\lib\site-packages\django\bin\iot\iot\IotMidWare.py", line 26, in process_request
    ob = json.loads(str(request.body, encoding = "utf-8"))
  File "E:\common\Python\lib\json\__init__.py", line 354, in loads
    return _default_decoder.decode(s)
  File "E:\common\Python\lib\json\decoder.py", line 339, in decode
    obj, end = self.raw_decode(s, idx=_w(s, 0).end())
  File "E:\common\Python\lib\json\decoder.py", line 357, in raw_decode
    raise JSONDecodeError("Expecting value", s, err.value) from None
json.decoder.JSONDecodeError: Expecting value: line 1 column 1 (char 0)
2018-07-10 20:21:54,246 - django.request - ERROR - exception.py line:118-- Internal Server Error: /favicon.ico 
Traceback (most recent call last):
  File "E:\common\Python\lib\site-packages\django\core\handlers\exception.py", line 35, in inner
    response = get_response(request)
  File "E:\common\Python\lib\site-packages\django\utils\deprecation.py", line 93, in __call__
    response = self.process_request(request)
  File "E:\common\Python\lib\site-packages\django\bin\iot\iot\IotMidWare.py", line 26, in process_request
    ob = json.loads(str(request.body, encoding = "utf-8"))
  File "E:\common\Python\lib\json\__init__.py", line 354, in loads
    return _default_decoder.decode(s)
  File "E:\common\Python\lib\json\decoder.py", line 339, in decode
    obj, end = self.raw_decode(s, idx=_w(s, 0).end())
  File "E:\common\Python\lib\json\decoder.py", line 357, in raw_decode
    raise JSONDecodeError("Expecting value", s, err.value) from None
json.decoder.JSONDecodeError: Expecting value: line 1 column 1 (char 0)
2018-07-11 12:27:38,791 - apscheduler.threadpool - INFO - threadpool.py line:52-- Started thread pool with 0 core threads and 20 maximum threads 
2018-07-11 12:42:01,754 - django.request - ERROR - exception.py line:118-- Internal Server Error: /login/login 
Traceback (most recent call last):
  File "E:\common\Python\lib\site-packages\django_redis\cache.py", line 32, in _decorator
    return method(self, *args, **kwargs)
  File "E:\common\Python\lib\site-packages\django_redis\cache.py", line 124, in has_key
    return self.client.has_key(*args, **kwargs)
  File "E:\common\Python\lib\site-packages\django_redis\client\default.py", line 477, in has_key
    raise ConnectionInterrupted(connection=client, parent=e)
django_redis.exceptions.ConnectionInterrupted: Redis ConnectionError: Error 10061 connecting to 127.0.0.1:6379. 由于目标计算机积极拒绝，无法连接。.

During handling of the above exception, another exception occurred:

Traceback (most recent call last):
  File "E:\common\Python\lib\site-packages\django\core\handlers\exception.py", line 35, in inner
    response = get_response(request)
  File "E:\common\Python\lib\site-packages\django\utils\deprecation.py", line 97, in __call__
    response = self.process_response(request, response)
  File "E:\common\Python\lib\site-packages\django\contrib\sessions\middleware.py", line 58, in process_response
    request.session.save()
  File "E:\common\Python\lib\site-packages\django\contrib\sessions\backends\cache.py", line 56, in save
    return self.create()
  File "E:\common\Python\lib\site-packages\django\contrib\sessions\backends\cache.py", line 43, in create
    self._session_key = self._get_new_session_key()
  File "E:\common\Python\lib\site-packages\django\contrib\sessions\backends\base.py", line 153, in _get_new_session_key
    if not self.exists(session_key):
  File "E:\common\Python\lib\site-packages\django\contrib\sessions\backends\cache.py", line 70, in exists
    return bool(session_key) and (self.cache_key_prefix + session_key) in self._cache
  File "E:\common\Python\lib\site-packages\django\core\cache\backends\base.py", line 201, in __contains__
    return self.has_key(key)
  File "E:\common\Python\lib\site-packages\django_redis\cache.py", line 39, in _decorator
    raise e.parent
  File "E:\common\Python\lib\site-packages\django_redis\client\default.py", line 475, in has_key
    return client.exists(key)
  File "E:\common\Python\lib\site-packages\redis\client.py", line 951, in exists
    return self.execute_command('EXISTS', name)
  File "E:\common\Python\lib\site-packages\redis\client.py", line 673, in execute_command
    connection.send_command(*args)
  File "E:\common\Python\lib\site-packages\redis\connection.py", line 610, in send_command
    self.send_packed_command(self.pack_command(*args))
  File "E:\common\Python\lib\site-packages\redis\connection.py", line 585, in send_packed_command
    self.connect()
  File "E:\common\Python\lib\site-packages\redis\connection.py", line 489, in connect
    raise ConnectionError(self._error_message(e))
redis.exceptions.ConnectionError: Error 10061 connecting to 127.0.0.1:6379. 由于目标计算机积极拒绝，无法连接。.
2018-07-11 12:42:05,731 - django.request - ERROR - exception.py line:118-- Internal Server Error: /login/login 
Traceback (most recent call last):
  File "E:\common\Python\lib\site-packages\django_redis\cache.py", line 32, in _decorator
    return method(self, *args, **kwargs)
  File "E:\common\Python\lib\site-packages\django_redis\cache.py", line 124, in has_key
    return self.client.has_key(*args, **kwargs)
  File "E:\common\Python\lib\site-packages\django_redis\client\default.py", line 477, in has_key
    raise ConnectionInterrupted(connection=client, parent=e)
django_redis.exceptions.ConnectionInterrupted: Redis ConnectionError: Error 10061 connecting to 127.0.0.1:6379. 由于目标计算机积极拒绝，无法连接。.

During handling of the above exception, another exception occurred:

Traceback (most recent call last):
  File "E:\common\Python\lib\site-packages\django\core\handlers\exception.py", line 35, in inner
    response = get_response(request)
  File "E:\common\Python\lib\site-packages\django\utils\deprecation.py", line 97, in __call__
    response = self.process_response(request, response)
  File "E:\common\Python\lib\site-packages\django\contrib\sessions\middleware.py", line 58, in process_response
    request.session.save()
  File "E:\common\Python\lib\site-packages\django\contrib\sessions\backends\cache.py", line 56, in save
    return self.create()
  File "E:\common\Python\lib\site-packages\django\contrib\sessions\backends\cache.py", line 43, in create
    self._session_key = self._get_new_session_key()
  File "E:\common\Python\lib\site-packages\django\contrib\sessions\backends\base.py", line 153, in _get_new_session_key
    if not self.exists(session_key):
  File "E:\common\Python\lib\site-packages\django\contrib\sessions\backends\cache.py", line 70, in exists
    return bool(session_key) and (self.cache_key_prefix + session_key) in self._cache
  File "E:\common\Python\lib\site-packages\django\core\cache\backends\base.py", line 201, in __contains__
    return self.has_key(key)
  File "E:\common\Python\lib\site-packages\django_redis\cache.py", line 39, in _decorator
    raise e.parent
  File "E:\common\Python\lib\site-packages\django_redis\client\default.py", line 475, in has_key
    return client.exists(key)
  File "E:\common\Python\lib\site-packages\redis\client.py", line 951, in exists
    return self.execute_command('EXISTS', name)
  File "E:\common\Python\lib\site-packages\redis\client.py", line 673, in execute_command
    connection.send_command(*args)
  File "E:\common\Python\lib\site-packages\redis\connection.py", line 610, in send_command
    self.send_packed_command(self.pack_command(*args))
  File "E:\common\Python\lib\site-packages\redis\connection.py", line 585, in send_packed_command
    self.connect()
  File "E:\common\Python\lib\site-packages\redis\connection.py", line 489, in connect
    raise ConnectionError(self._error_message(e))
redis.exceptions.ConnectionError: Error 10061 connecting to 127.0.0.1:6379. 由于目标计算机积极拒绝，无法连接。.
2018-07-11 12:42:06,476 - all - INFO - views.py line:119-- timestamp : 1531284126164 
2018-07-11 12:42:08,575 - django.request - ERROR - exception.py line:118-- Internal Server Error: /login/create_code_img/ 
Traceback (most recent call last):
  File "E:\common\Python\lib\site-packages\django_redis\cache.py", line 32, in _decorator
    return method(self, *args, **kwargs)
  File "E:\common\Python\lib\site-packages\django_redis\cache.py", line 124, in has_key
    return self.client.has_key(*args, **kwargs)
  File "E:\common\Python\lib\site-packages\django_redis\client\default.py", line 477, in has_key
    raise ConnectionInterrupted(connection=client, parent=e)
django_redis.exceptions.ConnectionInterrupted: Redis ConnectionError: Error 10061 connecting to 127.0.0.1:6379. 由于目标计算机积极拒绝，无法连接。.

During handling of the above exception, another exception occurred:

Traceback (most recent call last):
  File "E:\common\Python\lib\site-packages\django\core\handlers\exception.py", line 35, in inner
    response = get_response(request)
  File "E:\common\Python\lib\site-packages\django\utils\deprecation.py", line 97, in __call__
    response = self.process_response(request, response)
  File "E:\common\Python\lib\site-packages\django\contrib\sessions\middleware.py", line 58, in process_response
    request.session.save()
  File "E:\common\Python\lib\site-packages\django\contrib\sessions\backends\cache.py", line 56, in save
    return self.create()
  File "E:\common\Python\lib\site-packages\django\contrib\sessions\backends\cache.py", line 43, in create
    self._session_key = self._get_new_session_key()
  File "E:\common\Python\lib\site-packages\django\contrib\sessions\backends\base.py", line 153, in _get_new_session_key
    if not self.exists(session_key):
  File "E:\common\Python\lib\site-packages\django\contrib\sessions\backends\cache.py", line 70, in exists
    return bool(session_key) and (self.cache_key_prefix + session_key) in self._cache
  File "E:\common\Python\lib\site-packages\django\core\cache\backends\base.py", line 201, in __contains__
    return self.has_key(key)
  File "E:\common\Python\lib\site-packages\django_redis\cache.py", line 39, in _decorator
    raise e.parent
  File "E:\common\Python\lib\site-packages\django_redis\client\default.py", line 475, in has_key
    return client.exists(key)
  File "E:\common\Python\lib\site-packages\redis\client.py", line 951, in exists
    return self.execute_command('EXISTS', name)
  File "E:\common\Python\lib\site-packages\redis\client.py", line 673, in execute_command
    connection.send_command(*args)
  File "E:\common\Python\lib\site-packages\redis\connection.py", line 610, in send_command
    self.send_packed_command(self.pack_command(*args))
  File "E:\common\Python\lib\site-packages\redis\connection.py", line 585, in send_packed_command
    self.connect()
  File "E:\common\Python\lib\site-packages\redis\connection.py", line 489, in connect
    raise ConnectionError(self._error_message(e))
redis.exceptions.ConnectionError: Error 10061 connecting to 127.0.0.1:6379. 由于目标计算机积极拒绝，无法连接。.
2018-07-11 12:42:20,577 - django.request - ERROR - exception.py line:118-- Internal Server Error: /login/login 
Traceback (most recent call last):
  File "E:\common\Python\lib\site-packages\django_redis\cache.py", line 32, in _decorator
    return method(self, *args, **kwargs)
  File "E:\common\Python\lib\site-packages\django_redis\cache.py", line 124, in has_key
    return self.client.has_key(*args, **kwargs)
  File "E:\common\Python\lib\site-packages\django_redis\client\default.py", line 477, in has_key
    raise ConnectionInterrupted(connection=client, parent=e)
django_redis.exceptions.ConnectionInterrupted: Redis ConnectionError: Error 10061 connecting to 127.0.0.1:6379. 由于目标计算机积极拒绝，无法连接。.

During handling of the above exception, another exception occurred:

Traceback (most recent call last):
  File "E:\common\Python\lib\site-packages\django\core\handlers\exception.py", line 35, in inner
    response = get_response(request)
  File "E:\common\Python\lib\site-packages\django\utils\deprecation.py", line 97, in __call__
    response = self.process_response(request, response)
  File "E:\common\Python\lib\site-packages\django\contrib\sessions\middleware.py", line 58, in process_response
    request.session.save()
  File "E:\common\Python\lib\site-packages\django\contrib\sessions\backends\cache.py", line 56, in save
    return self.create()
  File "E:\common\Python\lib\site-packages\django\contrib\sessions\backends\cache.py", line 43, in create
    self._session_key = self._get_new_session_key()
  File "E:\common\Python\lib\site-packages\django\contrib\sessions\backends\base.py", line 153, in _get_new_session_key
    if not self.exists(session_key):
  File "E:\common\Python\lib\site-packages\django\contrib\sessions\backends\cache.py", line 70, in exists
    return bool(session_key) and (self.cache_key_prefix + session_key) in self._cache
  File "E:\common\Python\lib\site-packages\django\core\cache\backends\base.py", line 201, in __contains__
    return self.has_key(key)
  File "E:\common\Python\lib\site-packages\django_redis\cache.py", line 39, in _decorator
    raise e.parent
  File "E:\common\Python\lib\site-packages\django_redis\client\default.py", line 475, in has_key
    return client.exists(key)
  File "E:\common\Python\lib\site-packages\redis\client.py", line 951, in exists
    return self.execute_command('EXISTS', name)
  File "E:\common\Python\lib\site-packages\redis\client.py", line 673, in execute_command
    connection.send_command(*args)
  File "E:\common\Python\lib\site-packages\redis\connection.py", line 610, in send_command
    self.send_packed_command(self.pack_command(*args))
  File "E:\common\Python\lib\site-packages\redis\connection.py", line 585, in send_packed_command
    self.connect()
  File "E:\common\Python\lib\site-packages\redis\connection.py", line 489, in connect
    raise ConnectionError(self._error_message(e))
redis.exceptions.ConnectionError: Error 10061 connecting to 127.0.0.1:6379. 由于目标计算机积极拒绝，无法连接。.
2018-07-11 12:42:22,670 - django.request - ERROR - exception.py line:118-- Internal Server Error: /login/login 
Traceback (most recent call last):
  File "E:\common\Python\lib\site-packages\django_redis\cache.py", line 32, in _decorator
    return method(self, *args, **kwargs)
  File "E:\common\Python\lib\site-packages\django_redis\cache.py", line 124, in has_key
    return self.client.has_key(*args, **kwargs)
  File "E:\common\Python\lib\site-packages\django_redis\client\default.py", line 477, in has_key
    raise ConnectionInterrupted(connection=client, parent=e)
django_redis.exceptions.ConnectionInterrupted: Redis ConnectionError: Error 10061 connecting to 127.0.0.1:6379. 由于目标计算机积极拒绝，无法连接。.

During handling of the above exception, another exception occurred:

Traceback (most recent call last):
  File "E:\common\Python\lib\site-packages\django\core\handlers\exception.py", line 35, in inner
    response = get_response(request)
  File "E:\common\Python\lib\site-packages\django\utils\deprecation.py", line 97, in __call__
    response = self.process_response(request, response)
  File "E:\common\Python\lib\site-packages\django\contrib\sessions\middleware.py", line 58, in process_response
    request.session.save()
  File "E:\common\Python\lib\site-packages\django\contrib\sessions\backends\cache.py", line 56, in save
    return self.create()
  File "E:\common\Python\lib\site-packages\django\contrib\sessions\backends\cache.py", line 43, in create
    self._session_key = self._get_new_session_key()
  File "E:\common\Python\lib\site-packages\django\contrib\sessions\backends\base.py", line 153, in _get_new_session_key
    if not self.exists(session_key):
  File "E:\common\Python\lib\site-packages\django\contrib\sessions\backends\cache.py", line 70, in exists
    return bool(session_key) and (self.cache_key_prefix + session_key) in self._cache
  File "E:\common\Python\lib\site-packages\django\core\cache\backends\base.py", line 201, in __contains__
    return self.has_key(key)
  File "E:\common\Python\lib\site-packages\django_redis\cache.py", line 39, in _decorator
    raise e.parent
  File "E:\common\Python\lib\site-packages\django_redis\client\default.py", line 475, in has_key
    return client.exists(key)
  File "E:\common\Python\lib\site-packages\redis\client.py", line 951, in exists
    return self.execute_command('EXISTS', name)
  File "E:\common\Python\lib\site-packages\redis\client.py", line 673, in execute_command
    connection.send_command(*args)
  File "E:\common\Python\lib\site-packages\redis\connection.py", line 610, in send_command
    self.send_packed_command(self.pack_command(*args))
  File "E:\common\Python\lib\site-packages\redis\connection.py", line 585, in send_packed_command
    self.connect()
  File "E:\common\Python\lib\site-packages\redis\connection.py", line 489, in connect
    raise ConnectionError(self._error_message(e))
redis.exceptions.ConnectionError: Error 10061 connecting to 127.0.0.1:6379. 由于目标计算机积极拒绝，无法连接。.
2018-07-11 12:42:23,872 - django.request - ERROR - exception.py line:118-- Internal Server Error: /login/login 
Traceback (most recent call last):
  File "E:\common\Python\lib\site-packages\django_redis\cache.py", line 32, in _decorator
    return method(self, *args, **kwargs)
  File "E:\common\Python\lib\site-packages\django_redis\cache.py", line 124, in has_key
    return self.client.has_key(*args, **kwargs)
  File "E:\common\Python\lib\site-packages\django_redis\client\default.py", line 477, in has_key
    raise ConnectionInterrupted(connection=client, parent=e)
django_redis.exceptions.ConnectionInterrupted: Redis ConnectionError: Error 10061 connecting to 127.0.0.1:6379. 由于目标计算机积极拒绝，无法连接。.

During handling of the above exception, another exception occurred:

Traceback (most recent call last):
  File "E:\common\Python\lib\site-packages\django\core\handlers\exception.py", line 35, in inner
    response = get_response(request)
  File "E:\common\Python\lib\site-packages\django\utils\deprecation.py", line 97, in __call__
    response = self.process_response(request, response)
  File "E:\common\Python\lib\site-packages\django\contrib\sessions\middleware.py", line 58, in process_response
    request.session.save()
  File "E:\common\Python\lib\site-packages\django\contrib\sessions\backends\cache.py", line 56, in save
    return self.create()
  File "E:\common\Python\lib\site-packages\django\contrib\sessions\backends\cache.py", line 43, in create
    self._session_key = self._get_new_session_key()
  File "E:\common\Python\lib\site-packages\django\contrib\sessions\backends\base.py", line 153, in _get_new_session_key
    if not self.exists(session_key):
  File "E:\common\Python\lib\site-packages\django\contrib\sessions\backends\cache.py", line 70, in exists
    return bool(session_key) and (self.cache_key_prefix + session_key) in self._cache
  File "E:\common\Python\lib\site-packages\django\core\cache\backends\base.py", line 201, in __contains__
    return self.has_key(key)
  File "E:\common\Python\lib\site-packages\django_redis\cache.py", line 39, in _decorator
    raise e.parent
  File "E:\common\Python\lib\site-packages\django_redis\client\default.py", line 475, in has_key
    return client.exists(key)
  File "E:\common\Python\lib\site-packages\redis\client.py", line 951, in exists
    return self.execute_command('EXISTS', name)
  File "E:\common\Python\lib\site-packages\redis\client.py", line 673, in execute_command
    connection.send_command(*args)
  File "E:\common\Python\lib\site-packages\redis\connection.py", line 610, in send_command
    self.send_packed_command(self.pack_command(*args))
  File "E:\common\Python\lib\site-packages\redis\connection.py", line 585, in send_packed_command
    self.connect()
  File "E:\common\Python\lib\site-packages\redis\connection.py", line 489, in connect
    raise ConnectionError(self._error_message(e))
redis.exceptions.ConnectionError: Error 10061 connecting to 127.0.0.1:6379. 由于目标计算机积极拒绝，无法连接。.
2018-07-11 12:42:24,465 - django.request - ERROR - exception.py line:118-- Internal Server Error: /login/login 
Traceback (most recent call last):
  File "E:\common\Python\lib\site-packages\django_redis\cache.py", line 32, in _decorator
    return method(self, *args, **kwargs)
  File "E:\common\Python\lib\site-packages\django_redis\cache.py", line 124, in has_key
    return self.client.has_key(*args, **kwargs)
  File "E:\common\Python\lib\site-packages\django_redis\client\default.py", line 477, in has_key
    raise ConnectionInterrupted(connection=client, parent=e)
django_redis.exceptions.ConnectionInterrupted: Redis ConnectionError: Error 10061 connecting to 127.0.0.1:6379. 由于目标计算机积极拒绝，无法连接。.

During handling of the above exception, another exception occurred:

Traceback (most recent call last):
  File "E:\common\Python\lib\site-packages\django\core\handlers\exception.py", line 35, in inner
    response = get_response(request)
  File "E:\common\Python\lib\site-packages\django\utils\deprecation.py", line 97, in __call__
    response = self.process_response(request, response)
  File "E:\common\Python\lib\site-packages\django\contrib\sessions\middleware.py", line 58, in process_response
    request.session.save()
  File "E:\common\Python\lib\site-packages\django\contrib\sessions\backends\cache.py", line 56, in save
    return self.create()
  File "E:\common\Python\lib\site-packages\django\contrib\sessions\backends\cache.py", line 43, in create
    self._session_key = self._get_new_session_key()
  File "E:\common\Python\lib\site-packages\django\contrib\sessions\backends\base.py", line 153, in _get_new_session_key
    if not self.exists(session_key):
  File "E:\common\Python\lib\site-packages\django\contrib\sessions\backends\cache.py", line 70, in exists
    return bool(session_key) and (self.cache_key_prefix + session_key) in self._cache
  File "E:\common\Python\lib\site-packages\django\core\cache\backends\base.py", line 201, in __contains__
    return self.has_key(key)
  File "E:\common\Python\lib\site-packages\django_redis\cache.py", line 39, in _decorator
    raise e.parent
  File "E:\common\Python\lib\site-packages\django_redis\client\default.py", line 475, in has_key
    return client.exists(key)
  File "E:\common\Python\lib\site-packages\redis\client.py", line 951, in exists
    return self.execute_command('EXISTS', name)
  File "E:\common\Python\lib\site-packages\redis\client.py", line 673, in execute_command
    connection.send_command(*args)
  File "E:\common\Python\lib\site-packages\redis\connection.py", line 610, in send_command
    self.send_packed_command(self.pack_command(*args))
  File "E:\common\Python\lib\site-packages\redis\connection.py", line 585, in send_packed_command
    self.connect()
  File "E:\common\Python\lib\site-packages\redis\connection.py", line 489, in connect
    raise ConnectionError(self._error_message(e))
redis.exceptions.ConnectionError: Error 10061 connecting to 127.0.0.1:6379. 由于目标计算机积极拒绝，无法连接。.
2018-07-11 12:42:24,661 - django.request - ERROR - exception.py line:118-- Internal Server Error: /login/login 
Traceback (most recent call last):
  File "E:\common\Python\lib\site-packages\django_redis\cache.py", line 32, in _decorator
    return method(self, *args, **kwargs)
  File "E:\common\Python\lib\site-packages\django_redis\cache.py", line 124, in has_key
    return self.client.has_key(*args, **kwargs)
  File "E:\common\Python\lib\site-packages\django_redis\client\default.py", line 477, in has_key
    raise ConnectionInterrupted(connection=client, parent=e)
django_redis.exceptions.ConnectionInterrupted: Redis ConnectionError: Error 10061 connecting to 127.0.0.1:6379. 由于目标计算机积极拒绝，无法连接。.

During handling of the above exception, another exception occurred:

Traceback (most recent call last):
  File "E:\common\Python\lib\site-packages\django\core\handlers\exception.py", line 35, in inner
    response = get_response(request)
  File "E:\common\Python\lib\site-packages\django\utils\deprecation.py", line 97, in __call__
    response = self.process_response(request, response)
  File "E:\common\Python\lib\site-packages\django\contrib\sessions\middleware.py", line 58, in process_response
    request.session.save()
  File "E:\common\Python\lib\site-packages\django\contrib\sessions\backends\cache.py", line 56, in save
    return self.create()
  File "E:\common\Python\lib\site-packages\django\contrib\sessions\backends\cache.py", line 43, in create
    self._session_key = self._get_new_session_key()
  File "E:\common\Python\lib\site-packages\django\contrib\sessions\backends\base.py", line 153, in _get_new_session_key
    if not self.exists(session_key):
  File "E:\common\Python\lib\site-packages\django\contrib\sessions\backends\cache.py", line 70, in exists
    return bool(session_key) and (self.cache_key_prefix + session_key) in self._cache
  File "E:\common\Python\lib\site-packages\django\core\cache\backends\base.py", line 201, in __contains__
    return self.has_key(key)
  File "E:\common\Python\lib\site-packages\django_redis\cache.py", line 39, in _decorator
    raise e.parent
  File "E:\common\Python\lib\site-packages\django_redis\client\default.py", line 475, in has_key
    return client.exists(key)
  File "E:\common\Python\lib\site-packages\redis\client.py", line 951, in exists
    return self.execute_command('EXISTS', name)
  File "E:\common\Python\lib\site-packages\redis\client.py", line 673, in execute_command
    connection.send_command(*args)
  File "E:\common\Python\lib\site-packages\redis\connection.py", line 610, in send_command
    self.send_packed_command(self.pack_command(*args))
  File "E:\common\Python\lib\site-packages\redis\connection.py", line 585, in send_packed_command
    self.connect()
  File "E:\common\Python\lib\site-packages\redis\connection.py", line 489, in connect
    raise ConnectionError(self._error_message(e))
redis.exceptions.ConnectionError: Error 10061 connecting to 127.0.0.1:6379. 由于目标计算机积极拒绝，无法连接。.
