2019-01-05 00:18:16,533 - root - INFO - threadpool.py line:111-- Shutting down thread pool 
2019-01-05 16:12:30,012 - apscheduler.threadpool - INFO - threadpool.py line:52-- Started thread pool with 0 core threads and 20 maximum threads 
2019-01-05 16:13:17,346 - root - INFO - threadpool.py line:111-- Shutting down thread pool 
2019-01-05 16:13:22,316 - apscheduler.threadpool - INFO - threadpool.py line:52-- Started thread pool with 0 core threads and 20 maximum threads 
2019-01-05 16:32:19,738 - root - INFO - threadpool.py line:111-- Shutting down thread pool 
2019-01-05 16:32:23,955 - apscheduler.threadpool - INFO - threadpool.py line:52-- Started thread pool with 0 core threads and 20 maximum threads 
2019-01-05 16:35:22,127 - root - INFO - threadpool.py line:111-- Shutting down thread pool 
2019-01-05 16:35:23,955 - apscheduler.threadpool - INFO - threadpool.py line:52-- Started thread pool with 0 core threads and 20 maximum threads 
2019-01-05 16:56:05,622 - all - INFO - views.py line:164-- timestamp : 1546678565248 
2019-01-05 16:56:07,733 - django.request - ERROR - exception.py line:118-- Internal Server Error: /login/create_code_img/ 
Traceback (most recent call last):
  File "E:\common\Python\lib\site-packages\django_redis\cache.py", line 32, in _decorator
    return method(self, *args, **kwargs)
  File "E:\common\Python\lib\site-packages\django_redis\cache.py", line 124, in has_key
    return self.client.has_key(*args, **kwargs)
  File "E:\common\Python\lib\site-packages\django_redis\client\default.py", line 477, in has_key
    raise ConnectionInterrupted(connection=client, parent=e)
django_redis.exceptions.ConnectionInterrupted: Redis ConnectionError: Error 10061 connecting to 127.0.0.1:6379. 由于目标计算机积极拒绝，无法连接。.

During handling of the above exception, another exception occurred:

Traceback (most recent call last):
  File "E:\common\Python\lib\site-packages\django\core\handlers\exception.py", line 35, in inner
    response = get_response(request)
  File "E:\common\Python\lib\site-packages\django\utils\deprecation.py", line 97, in __call__
    response = self.process_response(request, response)
  File "E:\common\Python\lib\site-packages\django\contrib\sessions\middleware.py", line 58, in process_response
    request.session.save()
  File "E:\common\Python\lib\site-packages\django\contrib\sessions\backends\cache.py", line 56, in save
    return self.create()
  File "E:\common\Python\lib\site-packages\django\contrib\sessions\backends\cache.py", line 43, in create
    self._session_key = self._get_new_session_key()
  File "E:\common\Python\lib\site-packages\django\contrib\sessions\backends\base.py", line 153, in _get_new_session_key
    if not self.exists(session_key):
  File "E:\common\Python\lib\site-packages\django\contrib\sessions\backends\cache.py", line 70, in exists
    return bool(session_key) and (self.cache_key_prefix + session_key) in self._cache
  File "E:\common\Python\lib\site-packages\django\core\cache\backends\base.py", line 201, in __contains__
    return self.has_key(key)
  File "E:\common\Python\lib\site-packages\django_redis\cache.py", line 39, in _decorator
    raise e.parent
  File "E:\common\Python\lib\site-packages\django_redis\client\default.py", line 475, in has_key
    return client.exists(key)
  File "E:\common\Python\lib\site-packages\redis\client.py", line 951, in exists
    return self.execute_command('EXISTS', name)
  File "E:\common\Python\lib\site-packages\redis\client.py", line 673, in execute_command
    connection.send_command(*args)
  File "E:\common\Python\lib\site-packages\redis\connection.py", line 610, in send_command
    self.send_packed_command(self.pack_command(*args))
  File "E:\common\Python\lib\site-packages\redis\connection.py", line 585, in send_packed_command
    self.connect()
  File "E:\common\Python\lib\site-packages\redis\connection.py", line 489, in connect
    raise ConnectionError(self._error_message(e))
redis.exceptions.ConnectionError: Error 10061 connecting to 127.0.0.1:6379. 由于目标计算机积极拒绝，无法连接。.
2019-01-05 16:56:22,000 - django.request - ERROR - exception.py line:118-- Internal Server Error: /login/login 
Traceback (most recent call last):
  File "E:\common\Python\lib\site-packages\django_redis\cache.py", line 32, in _decorator
    return method(self, *args, **kwargs)
  File "E:\common\Python\lib\site-packages\django_redis\cache.py", line 124, in has_key
    return self.client.has_key(*args, **kwargs)
  File "E:\common\Python\lib\site-packages\django_redis\client\default.py", line 477, in has_key
    raise ConnectionInterrupted(connection=client, parent=e)
django_redis.exceptions.ConnectionInterrupted: Redis ConnectionError: Error 10061 connecting to 127.0.0.1:6379. 由于目标计算机积极拒绝，无法连接。.

During handling of the above exception, another exception occurred:

Traceback (most recent call last):
  File "E:\common\Python\lib\site-packages\django\core\handlers\exception.py", line 35, in inner
    response = get_response(request)
  File "E:\common\Python\lib\site-packages\django\utils\deprecation.py", line 97, in __call__
    response = self.process_response(request, response)
  File "E:\common\Python\lib\site-packages\django\contrib\sessions\middleware.py", line 58, in process_response
    request.session.save()
  File "E:\common\Python\lib\site-packages\django\contrib\sessions\backends\cache.py", line 56, in save
    return self.create()
  File "E:\common\Python\lib\site-packages\django\contrib\sessions\backends\cache.py", line 43, in create
    self._session_key = self._get_new_session_key()
  File "E:\common\Python\lib\site-packages\django\contrib\sessions\backends\base.py", line 153, in _get_new_session_key
    if not self.exists(session_key):
  File "E:\common\Python\lib\site-packages\django\contrib\sessions\backends\cache.py", line 70, in exists
    return bool(session_key) and (self.cache_key_prefix + session_key) in self._cache
  File "E:\common\Python\lib\site-packages\django\core\cache\backends\base.py", line 201, in __contains__
    return self.has_key(key)
  File "E:\common\Python\lib\site-packages\django_redis\cache.py", line 39, in _decorator
    raise e.parent
  File "E:\common\Python\lib\site-packages\django_redis\client\default.py", line 475, in has_key
    return client.exists(key)
  File "E:\common\Python\lib\site-packages\redis\client.py", line 951, in exists
    return self.execute_command('EXISTS', name)
  File "E:\common\Python\lib\site-packages\redis\client.py", line 673, in execute_command
    connection.send_command(*args)
  File "E:\common\Python\lib\site-packages\redis\connection.py", line 610, in send_command
    self.send_packed_command(self.pack_command(*args))
  File "E:\common\Python\lib\site-packages\redis\connection.py", line 585, in send_packed_command
    self.connect()
  File "E:\common\Python\lib\site-packages\redis\connection.py", line 489, in connect
    raise ConnectionError(self._error_message(e))
redis.exceptions.ConnectionError: Error 10061 connecting to 127.0.0.1:6379. 由于目标计算机积极拒绝，无法连接。.
2019-01-05 16:58:20,639 - root - INFO - threadpool.py line:111-- Shutting down thread pool 
2019-01-05 16:58:22,558 - apscheduler.threadpool - INFO - threadpool.py line:52-- Started thread pool with 0 core threads and 20 maximum threads 
2019-01-05 17:00:46,766 - django.request - ERROR - exception.py line:118-- Internal Server Error: / 
Traceback (most recent call last):
  File "E:\common\Python\lib\site-packages\django\core\handlers\exception.py", line 35, in inner
    response = get_response(request)
  File "E:\common\Python\lib\site-packages\django\utils\deprecation.py", line 93, in __call__
    response = self.process_request(request)
  File "E:\common\Python\lib\site-packages\django\bin\iot\iot\IotMidWare.py", line 26, in process_request
    ob = json.loads(str(request.body, encoding = "utf-8"))
  File "E:\common\Python\lib\json\__init__.py", line 354, in loads
    return _default_decoder.decode(s)
  File "E:\common\Python\lib\json\decoder.py", line 339, in decode
    obj, end = self.raw_decode(s, idx=_w(s, 0).end())
  File "E:\common\Python\lib\json\decoder.py", line 357, in raw_decode
    raise JSONDecodeError("Expecting value", s, err.value) from None
json.decoder.JSONDecodeError: Expecting value: line 1 column 1 (char 0)
2019-01-05 17:00:47,272 - django.request - ERROR - exception.py line:118-- Internal Server Error: /favicon.ico 
Traceback (most recent call last):
  File "E:\common\Python\lib\site-packages\django\core\handlers\exception.py", line 35, in inner
    response = get_response(request)
  File "E:\common\Python\lib\site-packages\django\utils\deprecation.py", line 93, in __call__
    response = self.process_request(request)
  File "E:\common\Python\lib\site-packages\django\bin\iot\iot\IotMidWare.py", line 26, in process_request
    ob = json.loads(str(request.body, encoding = "utf-8"))
  File "E:\common\Python\lib\json\__init__.py", line 354, in loads
    return _default_decoder.decode(s)
  File "E:\common\Python\lib\json\decoder.py", line 339, in decode
    obj, end = self.raw_decode(s, idx=_w(s, 0).end())
  File "E:\common\Python\lib\json\decoder.py", line 357, in raw_decode
    raise JSONDecodeError("Expecting value", s, err.value) from None
json.decoder.JSONDecodeError: Expecting value: line 1 column 1 (char 0)
2019-01-05 17:00:50,552 - django.request - ERROR - exception.py line:118-- Internal Server Error: /login 
Traceback (most recent call last):
  File "E:\common\Python\lib\site-packages\django\core\handlers\exception.py", line 35, in inner
    response = get_response(request)
  File "E:\common\Python\lib\site-packages\django\utils\deprecation.py", line 93, in __call__
    response = self.process_request(request)
  File "E:\common\Python\lib\site-packages\django\bin\iot\iot\IotMidWare.py", line 26, in process_request
    ob = json.loads(str(request.body, encoding = "utf-8"))
  File "E:\common\Python\lib\json\__init__.py", line 354, in loads
    return _default_decoder.decode(s)
  File "E:\common\Python\lib\json\decoder.py", line 339, in decode
    obj, end = self.raw_decode(s, idx=_w(s, 0).end())
  File "E:\common\Python\lib\json\decoder.py", line 357, in raw_decode
    raise JSONDecodeError("Expecting value", s, err.value) from None
json.decoder.JSONDecodeError: Expecting value: line 1 column 1 (char 0)
2019-01-05 17:00:50,851 - django.request - ERROR - exception.py line:118-- Internal Server Error: /favicon.ico 
Traceback (most recent call last):
  File "E:\common\Python\lib\site-packages\django\core\handlers\exception.py", line 35, in inner
    response = get_response(request)
  File "E:\common\Python\lib\site-packages\django\utils\deprecation.py", line 93, in __call__
    response = self.process_request(request)
  File "E:\common\Python\lib\site-packages\django\bin\iot\iot\IotMidWare.py", line 26, in process_request
    ob = json.loads(str(request.body, encoding = "utf-8"))
  File "E:\common\Python\lib\json\__init__.py", line 354, in loads
    return _default_decoder.decode(s)
  File "E:\common\Python\lib\json\decoder.py", line 339, in decode
    obj, end = self.raw_decode(s, idx=_w(s, 0).end())
  File "E:\common\Python\lib\json\decoder.py", line 357, in raw_decode
    raise JSONDecodeError("Expecting value", s, err.value) from None
json.decoder.JSONDecodeError: Expecting value: line 1 column 1 (char 0)
2019-01-05 17:01:04,457 - django.request - ERROR - exception.py line:118-- Internal Server Error: / 
Traceback (most recent call last):
  File "E:\common\Python\lib\site-packages\django\core\handlers\exception.py", line 35, in inner
    response = get_response(request)
  File "E:\common\Python\lib\site-packages\django\utils\deprecation.py", line 93, in __call__
    response = self.process_request(request)
  File "E:\common\Python\lib\site-packages\django\bin\iot\iot\IotMidWare.py", line 26, in process_request
    ob = json.loads(str(request.body, encoding = "utf-8"))
  File "E:\common\Python\lib\json\__init__.py", line 354, in loads
    return _default_decoder.decode(s)
  File "E:\common\Python\lib\json\decoder.py", line 339, in decode
    obj, end = self.raw_decode(s, idx=_w(s, 0).end())
  File "E:\common\Python\lib\json\decoder.py", line 357, in raw_decode
    raise JSONDecodeError("Expecting value", s, err.value) from None
json.decoder.JSONDecodeError: Expecting value: line 1 column 1 (char 0)
2019-01-05 17:01:04,662 - django.request - ERROR - exception.py line:118-- Internal Server Error: /favicon.ico 
Traceback (most recent call last):
  File "E:\common\Python\lib\site-packages\django\core\handlers\exception.py", line 35, in inner
    response = get_response(request)
  File "E:\common\Python\lib\site-packages\django\utils\deprecation.py", line 93, in __call__
    response = self.process_request(request)
  File "E:\common\Python\lib\site-packages\django\bin\iot\iot\IotMidWare.py", line 26, in process_request
    ob = json.loads(str(request.body, encoding = "utf-8"))
  File "E:\common\Python\lib\json\__init__.py", line 354, in loads
    return _default_decoder.decode(s)
  File "E:\common\Python\lib\json\decoder.py", line 339, in decode
    obj, end = self.raw_decode(s, idx=_w(s, 0).end())
  File "E:\common\Python\lib\json\decoder.py", line 357, in raw_decode
    raise JSONDecodeError("Expecting value", s, err.value) from None
json.decoder.JSONDecodeError: Expecting value: line 1 column 1 (char 0)
2019-01-05 17:02:29,586 - django.request - ERROR - exception.py line:118-- Internal Server Error: /favicon.ico 
Traceback (most recent call last):
  File "E:\common\Python\lib\site-packages\django\core\handlers\exception.py", line 35, in inner
    response = get_response(request)
  File "E:\common\Python\lib\site-packages\django\utils\deprecation.py", line 93, in __call__
    response = self.process_request(request)
  File "E:\common\Python\lib\site-packages\django\bin\iot\iot\IotMidWare.py", line 26, in process_request
    ob = json.loads(str(request.body, encoding = "utf-8"))
  File "E:\common\Python\lib\json\__init__.py", line 354, in loads
    return _default_decoder.decode(s)
  File "E:\common\Python\lib\json\decoder.py", line 339, in decode
    obj, end = self.raw_decode(s, idx=_w(s, 0).end())
  File "E:\common\Python\lib\json\decoder.py", line 357, in raw_decode
    raise JSONDecodeError("Expecting value", s, err.value) from None
json.decoder.JSONDecodeError: Expecting value: line 1 column 1 (char 0)
2019-01-05 17:02:32,386 - django.request - ERROR - exception.py line:118-- Internal Server Error: / 
Traceback (most recent call last):
  File "E:\common\Python\lib\site-packages\django\core\handlers\exception.py", line 35, in inner
    response = get_response(request)
  File "E:\common\Python\lib\site-packages\django\utils\deprecation.py", line 93, in __call__
    response = self.process_request(request)
  File "E:\common\Python\lib\site-packages\django\bin\iot\iot\IotMidWare.py", line 26, in process_request
    ob = json.loads(str(request.body, encoding = "utf-8"))
  File "E:\common\Python\lib\json\__init__.py", line 354, in loads
    return _default_decoder.decode(s)
  File "E:\common\Python\lib\json\decoder.py", line 339, in decode
    obj, end = self.raw_decode(s, idx=_w(s, 0).end())
  File "E:\common\Python\lib\json\decoder.py", line 357, in raw_decode
    raise JSONDecodeError("Expecting value", s, err.value) from None
json.decoder.JSONDecodeError: Expecting value: line 1 column 1 (char 0)
2019-01-05 17:02:32,589 - django.request - ERROR - exception.py line:118-- Internal Server Error: /favicon.ico 
Traceback (most recent call last):
  File "E:\common\Python\lib\site-packages\django\core\handlers\exception.py", line 35, in inner
    response = get_response(request)
  File "E:\common\Python\lib\site-packages\django\utils\deprecation.py", line 93, in __call__
    response = self.process_request(request)
  File "E:\common\Python\lib\site-packages\django\bin\iot\iot\IotMidWare.py", line 26, in process_request
    ob = json.loads(str(request.body, encoding = "utf-8"))
  File "E:\common\Python\lib\json\__init__.py", line 354, in loads
    return _default_decoder.decode(s)
  File "E:\common\Python\lib\json\decoder.py", line 339, in decode
    obj, end = self.raw_decode(s, idx=_w(s, 0).end())
  File "E:\common\Python\lib\json\decoder.py", line 357, in raw_decode
    raise JSONDecodeError("Expecting value", s, err.value) from None
json.decoder.JSONDecodeError: Expecting value: line 1 column 1 (char 0)
2019-01-05 17:02:37,040 - root - INFO - threadpool.py line:111-- Shutting down thread pool 
2019-01-05 17:02:40,832 - apscheduler.threadpool - INFO - threadpool.py line:52-- Started thread pool with 0 core threads and 20 maximum threads 
2019-01-05 17:03:25,616 - django.request - ERROR - exception.py line:118-- Internal Server Error: / 
Traceback (most recent call last):
  File "E:\common\Python\lib\site-packages\django\core\handlers\exception.py", line 35, in inner
    response = get_response(request)
  File "E:\common\Python\lib\site-packages\django\utils\deprecation.py", line 93, in __call__
    response = self.process_request(request)
  File "E:\common\Python\lib\site-packages\django\bin\iot\iot\IotMidWare.py", line 26, in process_request
    ob = json.loads(str(request.body, encoding = "utf-8"))
  File "E:\common\Python\lib\json\__init__.py", line 354, in loads
    return _default_decoder.decode(s)
  File "E:\common\Python\lib\json\decoder.py", line 339, in decode
    obj, end = self.raw_decode(s, idx=_w(s, 0).end())
  File "E:\common\Python\lib\json\decoder.py", line 357, in raw_decode
    raise JSONDecodeError("Expecting value", s, err.value) from None
json.decoder.JSONDecodeError: Expecting value: line 1 column 1 (char 0)
2019-01-05 17:03:26,048 - django.request - ERROR - exception.py line:118-- Internal Server Error: /favicon.ico 
Traceback (most recent call last):
  File "E:\common\Python\lib\site-packages\django\core\handlers\exception.py", line 35, in inner
    response = get_response(request)
  File "E:\common\Python\lib\site-packages\django\utils\deprecation.py", line 93, in __call__
    response = self.process_request(request)
  File "E:\common\Python\lib\site-packages\django\bin\iot\iot\IotMidWare.py", line 26, in process_request
    ob = json.loads(str(request.body, encoding = "utf-8"))
  File "E:\common\Python\lib\json\__init__.py", line 354, in loads
    return _default_decoder.decode(s)
  File "E:\common\Python\lib\json\decoder.py", line 339, in decode
    obj, end = self.raw_decode(s, idx=_w(s, 0).end())
  File "E:\common\Python\lib\json\decoder.py", line 357, in raw_decode
    raise JSONDecodeError("Expecting value", s, err.value) from None
json.decoder.JSONDecodeError: Expecting value: line 1 column 1 (char 0)
2019-01-05 17:03:29,576 - django.request - ERROR - exception.py line:118-- Internal Server Error: /favicon.ico 
Traceback (most recent call last):
  File "E:\common\Python\lib\site-packages\django\core\handlers\exception.py", line 35, in inner
    response = get_response(request)
  File "E:\common\Python\lib\site-packages\django\utils\deprecation.py", line 93, in __call__
    response = self.process_request(request)
  File "E:\common\Python\lib\site-packages\django\bin\iot\iot\IotMidWare.py", line 26, in process_request
    ob = json.loads(str(request.body, encoding = "utf-8"))
  File "E:\common\Python\lib\json\__init__.py", line 354, in loads
    return _default_decoder.decode(s)
  File "E:\common\Python\lib\json\decoder.py", line 339, in decode
    obj, end = self.raw_decode(s, idx=_w(s, 0).end())
  File "E:\common\Python\lib\json\decoder.py", line 357, in raw_decode
    raise JSONDecodeError("Expecting value", s, err.value) from None
json.decoder.JSONDecodeError: Expecting value: line 1 column 1 (char 0)
2019-01-05 17:03:32,599 - django.request - ERROR - exception.py line:118-- Internal Server Error: / 
Traceback (most recent call last):
  File "E:\common\Python\lib\site-packages\django\core\handlers\exception.py", line 35, in inner
    response = get_response(request)
  File "E:\common\Python\lib\site-packages\django\utils\deprecation.py", line 93, in __call__
    response = self.process_request(request)
  File "E:\common\Python\lib\site-packages\django\bin\iot\iot\IotMidWare.py", line 26, in process_request
    ob = json.loads(str(request.body, encoding = "utf-8"))
  File "E:\common\Python\lib\json\__init__.py", line 354, in loads
    return _default_decoder.decode(s)
  File "E:\common\Python\lib\json\decoder.py", line 339, in decode
    obj, end = self.raw_decode(s, idx=_w(s, 0).end())
  File "E:\common\Python\lib\json\decoder.py", line 357, in raw_decode
    raise JSONDecodeError("Expecting value", s, err.value) from None
json.decoder.JSONDecodeError: Expecting value: line 1 column 1 (char 0)
2019-01-05 17:03:32,801 - django.request - ERROR - exception.py line:118-- Internal Server Error: /favicon.ico 
Traceback (most recent call last):
  File "E:\common\Python\lib\site-packages\django\core\handlers\exception.py", line 35, in inner
    response = get_response(request)
  File "E:\common\Python\lib\site-packages\django\utils\deprecation.py", line 93, in __call__
    response = self.process_request(request)
  File "E:\common\Python\lib\site-packages\django\bin\iot\iot\IotMidWare.py", line 26, in process_request
    ob = json.loads(str(request.body, encoding = "utf-8"))
  File "E:\common\Python\lib\json\__init__.py", line 354, in loads
    return _default_decoder.decode(s)
  File "E:\common\Python\lib\json\decoder.py", line 339, in decode
    obj, end = self.raw_decode(s, idx=_w(s, 0).end())
  File "E:\common\Python\lib\json\decoder.py", line 357, in raw_decode
    raise JSONDecodeError("Expecting value", s, err.value) from None
json.decoder.JSONDecodeError: Expecting value: line 1 column 1 (char 0)
2019-01-05 17:05:55,993 - root - INFO - threadpool.py line:111-- Shutting down thread pool 
2019-01-05 17:06:06,725 - apscheduler.threadpool - INFO - threadpool.py line:52-- Started thread pool with 0 core threads and 20 maximum threads 
2019-01-05 17:06:51,757 - django.request - ERROR - exception.py line:118-- Internal Server Error: / 
Traceback (most recent call last):
  File "E:\common\Python\lib\site-packages\django\core\handlers\exception.py", line 35, in inner
    response = get_response(request)
  File "E:\common\Python\lib\site-packages\django\utils\deprecation.py", line 93, in __call__
    response = self.process_request(request)
  File "E:\common\Python\lib\site-packages\django\bin\iot\iot\IotMidWare.py", line 26, in process_request
    ob = json.loads(str(request.body, encoding = "utf-8"))
  File "E:\common\Python\lib\json\__init__.py", line 354, in loads
    return _default_decoder.decode(s)
  File "E:\common\Python\lib\json\decoder.py", line 339, in decode
    obj, end = self.raw_decode(s, idx=_w(s, 0).end())
  File "E:\common\Python\lib\json\decoder.py", line 357, in raw_decode
    raise JSONDecodeError("Expecting value", s, err.value) from None
json.decoder.JSONDecodeError: Expecting value: line 1 column 1 (char 0)
2019-01-05 17:06:52,064 - django.request - ERROR - exception.py line:118-- Internal Server Error: /favicon.ico 
Traceback (most recent call last):
  File "E:\common\Python\lib\site-packages\django\core\handlers\exception.py", line 35, in inner
    response = get_response(request)
  File "E:\common\Python\lib\site-packages\django\utils\deprecation.py", line 93, in __call__
    response = self.process_request(request)
  File "E:\common\Python\lib\site-packages\django\bin\iot\iot\IotMidWare.py", line 26, in process_request
    ob = json.loads(str(request.body, encoding = "utf-8"))
  File "E:\common\Python\lib\json\__init__.py", line 354, in loads
    return _default_decoder.decode(s)
  File "E:\common\Python\lib\json\decoder.py", line 339, in decode
    obj, end = self.raw_decode(s, idx=_w(s, 0).end())
  File "E:\common\Python\lib\json\decoder.py", line 357, in raw_decode
    raise JSONDecodeError("Expecting value", s, err.value) from None
json.decoder.JSONDecodeError: Expecting value: line 1 column 1 (char 0)
2019-01-05 17:06:56,971 - django.request - ERROR - exception.py line:118-- Internal Server Error: /favicon.ico 
Traceback (most recent call last):
  File "E:\common\Python\lib\site-packages\django\core\handlers\exception.py", line 35, in inner
    response = get_response(request)
  File "E:\common\Python\lib\site-packages\django\utils\deprecation.py", line 93, in __call__
    response = self.process_request(request)
  File "E:\common\Python\lib\site-packages\django\bin\iot\iot\IotMidWare.py", line 26, in process_request
    ob = json.loads(str(request.body, encoding = "utf-8"))
  File "E:\common\Python\lib\json\__init__.py", line 354, in loads
    return _default_decoder.decode(s)
  File "E:\common\Python\lib\json\decoder.py", line 339, in decode
    obj, end = self.raw_decode(s, idx=_w(s, 0).end())
  File "E:\common\Python\lib\json\decoder.py", line 357, in raw_decode
    raise JSONDecodeError("Expecting value", s, err.value) from None
json.decoder.JSONDecodeError: Expecting value: line 1 column 1 (char 0)
2019-01-05 17:08:37,884 - root - INFO - threadpool.py line:111-- Shutting down thread pool 
2019-01-05 17:08:39,575 - apscheduler.threadpool - INFO - threadpool.py line:52-- Started thread pool with 0 core threads and 20 maximum threads 
2019-01-05 17:08:39,783 - root - INFO - threadpool.py line:111-- Shutting down thread pool 
2019-01-05 17:08:43,073 - apscheduler.threadpool - INFO - threadpool.py line:52-- Started thread pool with 0 core threads and 20 maximum threads 
2019-01-05 17:09:54,108 - django.request - ERROR - exception.py line:118-- Internal Server Error: / 
Traceback (most recent call last):
  File "E:\common\Python\lib\site-packages\django\core\handlers\exception.py", line 35, in inner
    response = get_response(request)
  File "E:\common\Python\lib\site-packages\django\utils\deprecation.py", line 93, in __call__
    response = self.process_request(request)
  File "E:\common\Python\lib\site-packages\django\bin\iot\iot\IotMidWare.py", line 26, in process_request
    ob = json.loads(str(request.body, encoding = "utf-8"))
  File "E:\common\Python\lib\json\__init__.py", line 354, in loads
    return _default_decoder.decode(s)
  File "E:\common\Python\lib\json\decoder.py", line 339, in decode
    obj, end = self.raw_decode(s, idx=_w(s, 0).end())
  File "E:\common\Python\lib\json\decoder.py", line 357, in raw_decode
    raise JSONDecodeError("Expecting value", s, err.value) from None
json.decoder.JSONDecodeError: Expecting value: line 1 column 1 (char 0)
2019-01-05 17:09:54,420 - django.request - ERROR - exception.py line:118-- Internal Server Error: /favicon.ico 
Traceback (most recent call last):
  File "E:\common\Python\lib\site-packages\django\core\handlers\exception.py", line 35, in inner
    response = get_response(request)
  File "E:\common\Python\lib\site-packages\django\utils\deprecation.py", line 93, in __call__
    response = self.process_request(request)
  File "E:\common\Python\lib\site-packages\django\bin\iot\iot\IotMidWare.py", line 26, in process_request
    ob = json.loads(str(request.body, encoding = "utf-8"))
  File "E:\common\Python\lib\json\__init__.py", line 354, in loads
    return _default_decoder.decode(s)
  File "E:\common\Python\lib\json\decoder.py", line 339, in decode
    obj, end = self.raw_decode(s, idx=_w(s, 0).end())
  File "E:\common\Python\lib\json\decoder.py", line 357, in raw_decode
    raise JSONDecodeError("Expecting value", s, err.value) from None
json.decoder.JSONDecodeError: Expecting value: line 1 column 1 (char 0)
2019-01-05 17:09:55,652 - django.request - ERROR - exception.py line:118-- Internal Server Error: / 
Traceback (most recent call last):
  File "E:\common\Python\lib\site-packages\django\core\handlers\exception.py", line 35, in inner
    response = get_response(request)
  File "E:\common\Python\lib\site-packages\django\utils\deprecation.py", line 93, in __call__
    response = self.process_request(request)
  File "E:\common\Python\lib\site-packages\django\bin\iot\iot\IotMidWare.py", line 26, in process_request
    ob = json.loads(str(request.body, encoding = "utf-8"))
  File "E:\common\Python\lib\json\__init__.py", line 354, in loads
    return _default_decoder.decode(s)
  File "E:\common\Python\lib\json\decoder.py", line 339, in decode
    obj, end = self.raw_decode(s, idx=_w(s, 0).end())
  File "E:\common\Python\lib\json\decoder.py", line 357, in raw_decode
    raise JSONDecodeError("Expecting value", s, err.value) from None
json.decoder.JSONDecodeError: Expecting value: line 1 column 1 (char 0)
2019-01-05 17:09:55,864 - django.request - ERROR - exception.py line:118-- Internal Server Error: /favicon.ico 
Traceback (most recent call last):
  File "E:\common\Python\lib\site-packages\django\core\handlers\exception.py", line 35, in inner
    response = get_response(request)
  File "E:\common\Python\lib\site-packages\django\utils\deprecation.py", line 93, in __call__
    response = self.process_request(request)
  File "E:\common\Python\lib\site-packages\django\bin\iot\iot\IotMidWare.py", line 26, in process_request
    ob = json.loads(str(request.body, encoding = "utf-8"))
  File "E:\common\Python\lib\json\__init__.py", line 354, in loads
    return _default_decoder.decode(s)
  File "E:\common\Python\lib\json\decoder.py", line 339, in decode
    obj, end = self.raw_decode(s, idx=_w(s, 0).end())
  File "E:\common\Python\lib\json\decoder.py", line 357, in raw_decode
    raise JSONDecodeError("Expecting value", s, err.value) from None
json.decoder.JSONDecodeError: Expecting value: line 1 column 1 (char 0)
2019-01-05 17:09:58,377 - django.request - ERROR - exception.py line:118-- Internal Server Error: / 
Traceback (most recent call last):
  File "E:\common\Python\lib\site-packages\django\core\handlers\exception.py", line 35, in inner
    response = get_response(request)
  File "E:\common\Python\lib\site-packages\django\utils\deprecation.py", line 93, in __call__
    response = self.process_request(request)
  File "E:\common\Python\lib\site-packages\django\bin\iot\iot\IotMidWare.py", line 26, in process_request
    ob = json.loads(str(request.body, encoding = "utf-8"))
  File "E:\common\Python\lib\json\__init__.py", line 354, in loads
    return _default_decoder.decode(s)
  File "E:\common\Python\lib\json\decoder.py", line 339, in decode
    obj, end = self.raw_decode(s, idx=_w(s, 0).end())
  File "E:\common\Python\lib\json\decoder.py", line 357, in raw_decode
    raise JSONDecodeError("Expecting value", s, err.value) from None
json.decoder.JSONDecodeError: Expecting value: line 1 column 1 (char 0)
2019-01-05 17:09:58,558 - django.request - ERROR - exception.py line:118-- Internal Server Error: /favicon.ico 
Traceback (most recent call last):
  File "E:\common\Python\lib\site-packages\django\core\handlers\exception.py", line 35, in inner
    response = get_response(request)
  File "E:\common\Python\lib\site-packages\django\utils\deprecation.py", line 93, in __call__
    response = self.process_request(request)
  File "E:\common\Python\lib\site-packages\django\bin\iot\iot\IotMidWare.py", line 26, in process_request
    ob = json.loads(str(request.body, encoding = "utf-8"))
  File "E:\common\Python\lib\json\__init__.py", line 354, in loads
    return _default_decoder.decode(s)
  File "E:\common\Python\lib\json\decoder.py", line 339, in decode
    obj, end = self.raw_decode(s, idx=_w(s, 0).end())
  File "E:\common\Python\lib\json\decoder.py", line 357, in raw_decode
    raise JSONDecodeError("Expecting value", s, err.value) from None
json.decoder.JSONDecodeError: Expecting value: line 1 column 1 (char 0)
2019-01-05 17:11:38,934 - root - INFO - threadpool.py line:111-- Shutting down thread pool 
2019-01-05 17:11:40,648 - apscheduler.threadpool - INFO - threadpool.py line:52-- Started thread pool with 0 core threads and 20 maximum threads 
2019-01-05 17:11:48,455 - root - INFO - threadpool.py line:111-- Shutting down thread pool 
2019-01-05 17:11:52,355 - apscheduler.threadpool - INFO - threadpool.py line:52-- Started thread pool with 0 core threads and 20 maximum threads 
2019-01-05 17:13:08,758 - django.request - ERROR - exception.py line:118-- Internal Server Error: / 
Traceback (most recent call last):
  File "E:\common\Python\lib\site-packages\django\core\handlers\exception.py", line 35, in inner
    response = get_response(request)
  File "E:\common\Python\lib\site-packages\django\utils\deprecation.py", line 93, in __call__
    response = self.process_request(request)
  File "E:\common\Python\lib\site-packages\django\bin\iot\iot\IotMidWare.py", line 26, in process_request
    ob = json.loads(str(request.body, encoding = "utf-8"))
  File "E:\common\Python\lib\json\__init__.py", line 354, in loads
    return _default_decoder.decode(s)
  File "E:\common\Python\lib\json\decoder.py", line 339, in decode
    obj, end = self.raw_decode(s, idx=_w(s, 0).end())
  File "E:\common\Python\lib\json\decoder.py", line 357, in raw_decode
    raise JSONDecodeError("Expecting value", s, err.value) from None
json.decoder.JSONDecodeError: Expecting value: line 1 column 1 (char 0)
2019-01-05 17:13:09,072 - django.request - ERROR - exception.py line:118-- Internal Server Error: /favicon.ico 
Traceback (most recent call last):
  File "E:\common\Python\lib\site-packages\django\core\handlers\exception.py", line 35, in inner
    response = get_response(request)
  File "E:\common\Python\lib\site-packages\django\utils\deprecation.py", line 93, in __call__
    response = self.process_request(request)
  File "E:\common\Python\lib\site-packages\django\bin\iot\iot\IotMidWare.py", line 26, in process_request
    ob = json.loads(str(request.body, encoding = "utf-8"))
  File "E:\common\Python\lib\json\__init__.py", line 354, in loads
    return _default_decoder.decode(s)
  File "E:\common\Python\lib\json\decoder.py", line 339, in decode
    obj, end = self.raw_decode(s, idx=_w(s, 0).end())
  File "E:\common\Python\lib\json\decoder.py", line 357, in raw_decode
    raise JSONDecodeError("Expecting value", s, err.value) from None
json.decoder.JSONDecodeError: Expecting value: line 1 column 1 (char 0)
2019-01-05 17:13:12,196 - django.request - ERROR - exception.py line:118-- Internal Server Error: /favicon.ico 
Traceback (most recent call last):
  File "E:\common\Python\lib\site-packages\django\core\handlers\exception.py", line 35, in inner
    response = get_response(request)
  File "E:\common\Python\lib\site-packages\django\utils\deprecation.py", line 93, in __call__
    response = self.process_request(request)
  File "E:\common\Python\lib\site-packages\django\bin\iot\iot\IotMidWare.py", line 26, in process_request
    ob = json.loads(str(request.body, encoding = "utf-8"))
  File "E:\common\Python\lib\json\__init__.py", line 354, in loads
    return _default_decoder.decode(s)
  File "E:\common\Python\lib\json\decoder.py", line 339, in decode
    obj, end = self.raw_decode(s, idx=_w(s, 0).end())
  File "E:\common\Python\lib\json\decoder.py", line 357, in raw_decode
    raise JSONDecodeError("Expecting value", s, err.value) from None
json.decoder.JSONDecodeError: Expecting value: line 1 column 1 (char 0)
2019-01-05 17:13:15,444 - django.request - ERROR - exception.py line:118-- Internal Server Error: / 
Traceback (most recent call last):
  File "E:\common\Python\lib\site-packages\django\core\handlers\exception.py", line 35, in inner
    response = get_response(request)
  File "E:\common\Python\lib\site-packages\django\utils\deprecation.py", line 93, in __call__
    response = self.process_request(request)
  File "E:\common\Python\lib\site-packages\django\bin\iot\iot\IotMidWare.py", line 26, in process_request
    ob = json.loads(str(request.body, encoding = "utf-8"))
  File "E:\common\Python\lib\json\__init__.py", line 354, in loads
    return _default_decoder.decode(s)
  File "E:\common\Python\lib\json\decoder.py", line 339, in decode
    obj, end = self.raw_decode(s, idx=_w(s, 0).end())
  File "E:\common\Python\lib\json\decoder.py", line 357, in raw_decode
    raise JSONDecodeError("Expecting value", s, err.value) from None
json.decoder.JSONDecodeError: Expecting value: line 1 column 1 (char 0)
2019-01-05 17:13:15,664 - django.request - ERROR - exception.py line:118-- Internal Server Error: /favicon.ico 
Traceback (most recent call last):
  File "E:\common\Python\lib\site-packages\django\core\handlers\exception.py", line 35, in inner
    response = get_response(request)
  File "E:\common\Python\lib\site-packages\django\utils\deprecation.py", line 93, in __call__
    response = self.process_request(request)
  File "E:\common\Python\lib\site-packages\django\bin\iot\iot\IotMidWare.py", line 26, in process_request
    ob = json.loads(str(request.body, encoding = "utf-8"))
  File "E:\common\Python\lib\json\__init__.py", line 354, in loads
    return _default_decoder.decode(s)
  File "E:\common\Python\lib\json\decoder.py", line 339, in decode
    obj, end = self.raw_decode(s, idx=_w(s, 0).end())
  File "E:\common\Python\lib\json\decoder.py", line 357, in raw_decode
    raise JSONDecodeError("Expecting value", s, err.value) from None
json.decoder.JSONDecodeError: Expecting value: line 1 column 1 (char 0)
2019-01-05 17:13:28,783 - django.request - ERROR - exception.py line:118-- Internal Server Error: / 
Traceback (most recent call last):
  File "E:\common\Python\lib\site-packages\django\core\handlers\exception.py", line 35, in inner
    response = get_response(request)
  File "E:\common\Python\lib\site-packages\django\utils\deprecation.py", line 93, in __call__
    response = self.process_request(request)
  File "E:\common\Python\lib\site-packages\django\bin\iot\iot\IotMidWare.py", line 26, in process_request
    ob = json.loads(str(request.body, encoding = "utf-8"))
  File "E:\common\Python\lib\json\__init__.py", line 354, in loads
    return _default_decoder.decode(s)
  File "E:\common\Python\lib\json\decoder.py", line 339, in decode
    obj, end = self.raw_decode(s, idx=_w(s, 0).end())
  File "E:\common\Python\lib\json\decoder.py", line 357, in raw_decode
    raise JSONDecodeError("Expecting value", s, err.value) from None
json.decoder.JSONDecodeError: Expecting value: line 1 column 1 (char 0)
2019-01-05 17:13:28,994 - django.request - ERROR - exception.py line:118-- Internal Server Error: /favicon.ico 
Traceback (most recent call last):
  File "E:\common\Python\lib\site-packages\django\core\handlers\exception.py", line 35, in inner
    response = get_response(request)
  File "E:\common\Python\lib\site-packages\django\utils\deprecation.py", line 93, in __call__
    response = self.process_request(request)
  File "E:\common\Python\lib\site-packages\django\bin\iot\iot\IotMidWare.py", line 26, in process_request
    ob = json.loads(str(request.body, encoding = "utf-8"))
  File "E:\common\Python\lib\json\__init__.py", line 354, in loads
    return _default_decoder.decode(s)
  File "E:\common\Python\lib\json\decoder.py", line 339, in decode
    obj, end = self.raw_decode(s, idx=_w(s, 0).end())
  File "E:\common\Python\lib\json\decoder.py", line 357, in raw_decode
    raise JSONDecodeError("Expecting value", s, err.value) from None
json.decoder.JSONDecodeError: Expecting value: line 1 column 1 (char 0)
2019-01-05 17:14:40,295 - root - INFO - threadpool.py line:111-- Shutting down thread pool 
2019-01-05 17:14:42,004 - apscheduler.threadpool - INFO - threadpool.py line:52-- Started thread pool with 0 core threads and 20 maximum threads 
2019-01-05 17:15:16,644 - root - INFO - threadpool.py line:111-- Shutting down thread pool 
2019-01-05 17:15:18,385 - apscheduler.threadpool - INFO - threadpool.py line:52-- Started thread pool with 0 core threads and 20 maximum threads 
2019-01-05 17:15:55,724 - root - INFO - threadpool.py line:111-- Shutting down thread pool 
2019-01-05 17:15:57,426 - apscheduler.threadpool - INFO - threadpool.py line:52-- Started thread pool with 0 core threads and 20 maximum threads 
2019-01-05 17:16:27,461 - root - INFO - threadpool.py line:111-- Shutting down thread pool 
2019-01-05 17:16:31,183 - apscheduler.threadpool - INFO - threadpool.py line:52-- Started thread pool with 0 core threads and 20 maximum threads 
2019-01-05 17:16:47,867 - django.request - ERROR - exception.py line:118-- Internal Server Error: / 
Traceback (most recent call last):
  File "E:\common\Python\lib\site-packages\django\core\handlers\exception.py", line 35, in inner
    response = get_response(request)
  File "E:\common\Python\lib\site-packages\django\utils\deprecation.py", line 93, in __call__
    response = self.process_request(request)
  File "E:\common\Python\lib\site-packages\django\bin\iot\iot\IotMidWare.py", line 30, in process_request
    ob = json.loads(str(request.body, encoding = "utf-8"))
  File "E:\common\Python\lib\json\__init__.py", line 354, in loads
    return _default_decoder.decode(s)
  File "E:\common\Python\lib\json\decoder.py", line 339, in decode
    obj, end = self.raw_decode(s, idx=_w(s, 0).end())
  File "E:\common\Python\lib\json\decoder.py", line 357, in raw_decode
    raise JSONDecodeError("Expecting value", s, err.value) from None
json.decoder.JSONDecodeError: Expecting value: line 1 column 1 (char 0)
2019-01-05 17:16:48,175 - django.request - ERROR - exception.py line:118-- Internal Server Error: /favicon.ico 
Traceback (most recent call last):
  File "E:\common\Python\lib\site-packages\django\core\handlers\exception.py", line 35, in inner
    response = get_response(request)
  File "E:\common\Python\lib\site-packages\django\utils\deprecation.py", line 93, in __call__
    response = self.process_request(request)
  File "E:\common\Python\lib\site-packages\django\bin\iot\iot\IotMidWare.py", line 30, in process_request
    ob = json.loads(str(request.body, encoding = "utf-8"))
  File "E:\common\Python\lib\json\__init__.py", line 354, in loads
    return _default_decoder.decode(s)
  File "E:\common\Python\lib\json\decoder.py", line 339, in decode
    obj, end = self.raw_decode(s, idx=_w(s, 0).end())
  File "E:\common\Python\lib\json\decoder.py", line 357, in raw_decode
    raise JSONDecodeError("Expecting value", s, err.value) from None
json.decoder.JSONDecodeError: Expecting value: line 1 column 1 (char 0)
2019-01-05 17:17:02,495 - root - INFO - threadpool.py line:111-- Shutting down thread pool 
2019-01-05 17:17:07,971 - apscheduler.threadpool - INFO - threadpool.py line:52-- Started thread pool with 0 core threads and 20 maximum threads 
2019-01-05 17:17:32,170 - django.request - ERROR - exception.py line:118-- Internal Server Error: /favicon.ico 
Traceback (most recent call last):
  File "E:\common\Python\lib\site-packages\django\core\handlers\exception.py", line 35, in inner
    response = get_response(request)
  File "E:\common\Python\lib\site-packages\django\utils\deprecation.py", line 93, in __call__
    response = self.process_request(request)
  File "E:\common\Python\lib\site-packages\django\bin\iot\iot\IotMidWare.py", line 30, in process_request
    ob = json.loads(str(request.body, encoding = "utf-8"))
  File "E:\common\Python\lib\json\__init__.py", line 354, in loads
    return _default_decoder.decode(s)
  File "E:\common\Python\lib\json\decoder.py", line 339, in decode
    obj, end = self.raw_decode(s, idx=_w(s, 0).end())
  File "E:\common\Python\lib\json\decoder.py", line 357, in raw_decode
    raise JSONDecodeError("Expecting value", s, err.value) from None
json.decoder.JSONDecodeError: Expecting value: line 1 column 1 (char 0)
2019-01-05 17:17:39,275 - django.request - ERROR - exception.py line:118-- Internal Server Error: /favicon.ico 
Traceback (most recent call last):
  File "E:\common\Python\lib\site-packages\django\core\handlers\exception.py", line 35, in inner
    response = get_response(request)
  File "E:\common\Python\lib\site-packages\django\utils\deprecation.py", line 93, in __call__
    response = self.process_request(request)
  File "E:\common\Python\lib\site-packages\django\bin\iot\iot\IotMidWare.py", line 30, in process_request
    ob = json.loads(str(request.body, encoding = "utf-8"))
  File "E:\common\Python\lib\json\__init__.py", line 354, in loads
    return _default_decoder.decode(s)
  File "E:\common\Python\lib\json\decoder.py", line 339, in decode
    obj, end = self.raw_decode(s, idx=_w(s, 0).end())
  File "E:\common\Python\lib\json\decoder.py", line 357, in raw_decode
    raise JSONDecodeError("Expecting value", s, err.value) from None
json.decoder.JSONDecodeError: Expecting value: line 1 column 1 (char 0)
2019-01-05 17:17:42,419 - django.request - ERROR - exception.py line:118-- Internal Server Error: /favicon.ico 
Traceback (most recent call last):
  File "E:\common\Python\lib\site-packages\django\core\handlers\exception.py", line 35, in inner
    response = get_response(request)
  File "E:\common\Python\lib\site-packages\django\utils\deprecation.py", line 93, in __call__
    response = self.process_request(request)
  File "E:\common\Python\lib\site-packages\django\bin\iot\iot\IotMidWare.py", line 30, in process_request
    ob = json.loads(str(request.body, encoding = "utf-8"))
  File "E:\common\Python\lib\json\__init__.py", line 354, in loads
    return _default_decoder.decode(s)
  File "E:\common\Python\lib\json\decoder.py", line 339, in decode
    obj, end = self.raw_decode(s, idx=_w(s, 0).end())
  File "E:\common\Python\lib\json\decoder.py", line 357, in raw_decode
    raise JSONDecodeError("Expecting value", s, err.value) from None
json.decoder.JSONDecodeError: Expecting value: line 1 column 1 (char 0)
2019-01-05 17:17:46,575 - django.request - ERROR - exception.py line:118-- Internal Server Error: /translate 
Traceback (most recent call last):
  File "E:\common\Python\lib\site-packages\django\core\handlers\exception.py", line 35, in inner
    response = get_response(request)
  File "E:\common\Python\lib\site-packages\django\utils\deprecation.py", line 93, in __call__
    response = self.process_request(request)
  File "E:\common\Python\lib\site-packages\django\bin\iot\iot\IotMidWare.py", line 30, in process_request
    ob = json.loads(str(request.body, encoding = "utf-8"))
  File "E:\common\Python\lib\json\__init__.py", line 354, in loads
    return _default_decoder.decode(s)
  File "E:\common\Python\lib\json\decoder.py", line 339, in decode
    obj, end = self.raw_decode(s, idx=_w(s, 0).end())
  File "E:\common\Python\lib\json\decoder.py", line 357, in raw_decode
    raise JSONDecodeError("Expecting value", s, err.value) from None
json.decoder.JSONDecodeError: Expecting value: line 1 column 1 (char 0)
2019-01-05 17:17:46,788 - django.request - ERROR - exception.py line:118-- Internal Server Error: /favicon.ico 
Traceback (most recent call last):
  File "E:\common\Python\lib\site-packages\django\core\handlers\exception.py", line 35, in inner
    response = get_response(request)
  File "E:\common\Python\lib\site-packages\django\utils\deprecation.py", line 93, in __call__
    response = self.process_request(request)
  File "E:\common\Python\lib\site-packages\django\bin\iot\iot\IotMidWare.py", line 30, in process_request
    ob = json.loads(str(request.body, encoding = "utf-8"))
  File "E:\common\Python\lib\json\__init__.py", line 354, in loads
    return _default_decoder.decode(s)
  File "E:\common\Python\lib\json\decoder.py", line 339, in decode
    obj, end = self.raw_decode(s, idx=_w(s, 0).end())
  File "E:\common\Python\lib\json\decoder.py", line 357, in raw_decode
    raise JSONDecodeError("Expecting value", s, err.value) from None
json.decoder.JSONDecodeError: Expecting value: line 1 column 1 (char 0)
2019-01-05 17:17:50,661 - django.request - ERROR - exception.py line:118-- Internal Server Error: /favicon.ico 
Traceback (most recent call last):
  File "E:\common\Python\lib\site-packages\django\core\handlers\exception.py", line 35, in inner
    response = get_response(request)
  File "E:\common\Python\lib\site-packages\django\utils\deprecation.py", line 93, in __call__
    response = self.process_request(request)
  File "E:\common\Python\lib\site-packages\django\bin\iot\iot\IotMidWare.py", line 30, in process_request
    ob = json.loads(str(request.body, encoding = "utf-8"))
  File "E:\common\Python\lib\json\__init__.py", line 354, in loads
    return _default_decoder.decode(s)
  File "E:\common\Python\lib\json\decoder.py", line 339, in decode
    obj, end = self.raw_decode(s, idx=_w(s, 0).end())
  File "E:\common\Python\lib\json\decoder.py", line 357, in raw_decode
    raise JSONDecodeError("Expecting value", s, err.value) from None
json.decoder.JSONDecodeError: Expecting value: line 1 column 1 (char 0)
2019-01-05 17:17:54,083 - django.request - ERROR - exception.py line:118-- Internal Server Error: /favicon.ico 
Traceback (most recent call last):
  File "E:\common\Python\lib\site-packages\django\core\handlers\exception.py", line 35, in inner
    response = get_response(request)
  File "E:\common\Python\lib\site-packages\django\utils\deprecation.py", line 93, in __call__
    response = self.process_request(request)
  File "E:\common\Python\lib\site-packages\django\bin\iot\iot\IotMidWare.py", line 30, in process_request
    ob = json.loads(str(request.body, encoding = "utf-8"))
  File "E:\common\Python\lib\json\__init__.py", line 354, in loads
    return _default_decoder.decode(s)
  File "E:\common\Python\lib\json\decoder.py", line 339, in decode
    obj, end = self.raw_decode(s, idx=_w(s, 0).end())
  File "E:\common\Python\lib\json\decoder.py", line 357, in raw_decode
    raise JSONDecodeError("Expecting value", s, err.value) from None
json.decoder.JSONDecodeError: Expecting value: line 1 column 1 (char 0)
2019-01-05 17:18:00,657 - django.request - ERROR - exception.py line:118-- Internal Server Error: /favicon.ico 
Traceback (most recent call last):
  File "E:\common\Python\lib\site-packages\django\core\handlers\exception.py", line 35, in inner
    response = get_response(request)
  File "E:\common\Python\lib\site-packages\django\utils\deprecation.py", line 93, in __call__
    response = self.process_request(request)
  File "E:\common\Python\lib\site-packages\django\bin\iot\iot\IotMidWare.py", line 30, in process_request
    ob = json.loads(str(request.body, encoding = "utf-8"))
  File "E:\common\Python\lib\json\__init__.py", line 354, in loads
    return _default_decoder.decode(s)
  File "E:\common\Python\lib\json\decoder.py", line 339, in decode
    obj, end = self.raw_decode(s, idx=_w(s, 0).end())
  File "E:\common\Python\lib\json\decoder.py", line 357, in raw_decode
    raise JSONDecodeError("Expecting value", s, err.value) from None
json.decoder.JSONDecodeError: Expecting value: line 1 column 1 (char 0)
2019-01-05 17:55:40,430 - root - INFO - threadpool.py line:111-- Shutting down thread pool 
2019-01-05 17:55:44,617 - apscheduler.threadpool - INFO - threadpool.py line:52-- Started thread pool with 0 core threads and 20 maximum threads 
2019-01-05 17:56:28,048 - django.request - WARNING - base.py line:93-- Not Found: /favicon.ico 
2019-01-05 17:56:47,662 - django.request - WARNING - base.py line:93-- Not Found: /translate 
2019-01-05 17:56:56,597 - django.request - WARNING - base.py line:93-- Not Found: /login 
2019-01-05 17:57:00,260 - django.request - WARNING - base.py line:93-- Not Found: /login/ 
2019-01-05 17:57:04,751 - django.request - WARNING - base.py line:93-- Not Found: //login/ 
2019-01-05 18:01:49,825 - root - INFO - threadpool.py line:111-- Shutting down thread pool 
2019-01-05 18:01:53,405 - apscheduler.threadpool - INFO - threadpool.py line:52-- Started thread pool with 0 core threads and 20 maximum threads 
2019-01-05 18:05:58,870 - all - INFO - views.py line:164-- timestamp : 1546682758475 
2019-01-05 18:06:00,881 - django.request - ERROR - exception.py line:118-- Internal Server Error: /login/create_code_img/ 
Traceback (most recent call last):
  File "E:\common\Python\lib\site-packages\django_redis\cache.py", line 32, in _decorator
    return method(self, *args, **kwargs)
  File "E:\common\Python\lib\site-packages\django_redis\cache.py", line 124, in has_key
    return self.client.has_key(*args, **kwargs)
  File "E:\common\Python\lib\site-packages\django_redis\client\default.py", line 477, in has_key
    raise ConnectionInterrupted(connection=client, parent=e)
django_redis.exceptions.ConnectionInterrupted: Redis ConnectionError: Error 10061 connecting to 127.0.0.1:6379. 由于目标计算机积极拒绝，无法连接。.

During handling of the above exception, another exception occurred:

Traceback (most recent call last):
  File "E:\common\Python\lib\site-packages\django\core\handlers\exception.py", line 35, in inner
    response = get_response(request)
  File "E:\common\Python\lib\site-packages\django\utils\deprecation.py", line 97, in __call__
    response = self.process_response(request, response)
  File "E:\common\Python\lib\site-packages\django\contrib\sessions\middleware.py", line 58, in process_response
    request.session.save()
  File "E:\common\Python\lib\site-packages\django\contrib\sessions\backends\cache.py", line 56, in save
    return self.create()
  File "E:\common\Python\lib\site-packages\django\contrib\sessions\backends\cache.py", line 43, in create
    self._session_key = self._get_new_session_key()
  File "E:\common\Python\lib\site-packages\django\contrib\sessions\backends\base.py", line 153, in _get_new_session_key
    if not self.exists(session_key):
  File "E:\common\Python\lib\site-packages\django\contrib\sessions\backends\cache.py", line 70, in exists
    return bool(session_key) and (self.cache_key_prefix + session_key) in self._cache
  File "E:\common\Python\lib\site-packages\django\core\cache\backends\base.py", line 201, in __contains__
    return self.has_key(key)
  File "E:\common\Python\lib\site-packages\django_redis\cache.py", line 39, in _decorator
    raise e.parent
  File "E:\common\Python\lib\site-packages\django_redis\client\default.py", line 475, in has_key
    return client.exists(key)
  File "E:\common\Python\lib\site-packages\redis\client.py", line 951, in exists
    return self.execute_command('EXISTS', name)
  File "E:\common\Python\lib\site-packages\redis\client.py", line 673, in execute_command
    connection.send_command(*args)
  File "E:\common\Python\lib\site-packages\redis\connection.py", line 610, in send_command
    self.send_packed_command(self.pack_command(*args))
  File "E:\common\Python\lib\site-packages\redis\connection.py", line 585, in send_packed_command
    self.connect()
  File "E:\common\Python\lib\site-packages\redis\connection.py", line 489, in connect
    raise ConnectionError(self._error_message(e))
redis.exceptions.ConnectionError: Error 10061 connecting to 127.0.0.1:6379. 由于目标计算机积极拒绝，无法连接。.
2019-01-05 18:06:11,860 - django.request - WARNING - base.py line:93-- Not Found: /apilogin/translate/ 
2019-01-05 18:06:34,240 - django.request - WARNING - base.py line:93-- Not Found: /apilogin/translate/ 
2019-01-05 18:20:53,251 - root - INFO - threadpool.py line:111-- Shutting down thread pool 
2019-01-05 18:21:03,944 - apscheduler.threadpool - INFO - threadpool.py line:52-- Started thread pool with 0 core threads and 20 maximum threads 
2019-01-05 18:27:23,411 - root - INFO - threadpool.py line:111-- Shutting down thread pool 
2019-01-05 18:28:53,863 - apscheduler.threadpool - INFO - threadpool.py line:52-- Started thread pool with 0 core threads and 20 maximum threads 
2019-01-05 18:43:56,951 - root - INFO - threadpool.py line:111-- Shutting down thread pool 
2019-01-05 23:38:00,026 - apscheduler.threadpool - INFO - threadpool.py line:52-- Started thread pool with 0 core threads and 20 maximum threads 
2019-01-05 23:38:35,808 - django.request - WARNING - base.py line:93-- Not Found: /favicon.ico 
