2018-06-20 21:40:28,023 - all - INFO - views.py line:118-- timestamp : 1529502027509 
2018-06-20 22:03:57,664 - all - INFO - views.py line:118-- timestamp : 1529503437352 
2018-06-26 17:24:58,470 - django.request - ERROR - exception.py line:118-- Internal Server Error: / 
Traceback (most recent call last):
  File "E:\common\Python\lib\site-packages\django\core\handlers\exception.py", line 35, in inner
    response = get_response(request)
  File "E:\common\Python\lib\site-packages\django\utils\deprecation.py", line 93, in __call__
    response = self.process_request(request)
  File "E:\common\Python\lib\site-packages\django\bin\iot\iot\IotMidWare.py", line 26, in process_request
    ob = json.loads(str(request.body, encoding = "utf-8"))
  File "E:\common\Python\lib\json\__init__.py", line 354, in loads
    return _default_decoder.decode(s)
  File "E:\common\Python\lib\json\decoder.py", line 339, in decode
    obj, end = self.raw_decode(s, idx=_w(s, 0).end())
  File "E:\common\Python\lib\json\decoder.py", line 357, in raw_decode
    raise JSONDecodeError("Expecting value", s, err.value) from None
json.decoder.JSONDecodeError: Expecting value: line 1 column 1 (char 0)
2018-06-26 17:24:58,953 - django.request - ERROR - exception.py line:118-- Internal Server Error: /favicon.ico 
Traceback (most recent call last):
  File "E:\common\Python\lib\site-packages\django\core\handlers\exception.py", line 35, in inner
    response = get_response(request)
  File "E:\common\Python\lib\site-packages\django\utils\deprecation.py", line 93, in __call__
    response = self.process_request(request)
  File "E:\common\Python\lib\site-packages\django\bin\iot\iot\IotMidWare.py", line 26, in process_request
    ob = json.loads(str(request.body, encoding = "utf-8"))
  File "E:\common\Python\lib\json\__init__.py", line 354, in loads
    return _default_decoder.decode(s)
  File "E:\common\Python\lib\json\decoder.py", line 339, in decode
    obj, end = self.raw_decode(s, idx=_w(s, 0).end())
  File "E:\common\Python\lib\json\decoder.py", line 357, in raw_decode
    raise JSONDecodeError("Expecting value", s, err.value) from None
json.decoder.JSONDecodeError: Expecting value: line 1 column 1 (char 0)
2018-06-26 17:25:19,919 - django.request - ERROR - exception.py line:118-- Internal Server Error: /login 
Traceback (most recent call last):
  File "E:\common\Python\lib\site-packages\django\core\handlers\exception.py", line 35, in inner
    response = get_response(request)
  File "E:\common\Python\lib\site-packages\django\utils\deprecation.py", line 93, in __call__
    response = self.process_request(request)
  File "E:\common\Python\lib\site-packages\django\bin\iot\iot\IotMidWare.py", line 26, in process_request
    ob = json.loads(str(request.body, encoding = "utf-8"))
  File "E:\common\Python\lib\json\__init__.py", line 354, in loads
    return _default_decoder.decode(s)
  File "E:\common\Python\lib\json\decoder.py", line 339, in decode
    obj, end = self.raw_decode(s, idx=_w(s, 0).end())
  File "E:\common\Python\lib\json\decoder.py", line 357, in raw_decode
    raise JSONDecodeError("Expecting value", s, err.value) from None
json.decoder.JSONDecodeError: Expecting value: line 1 column 1 (char 0)
2018-06-26 17:25:20,279 - django.request - ERROR - exception.py line:118-- Internal Server Error: /favicon.ico 
Traceback (most recent call last):
  File "E:\common\Python\lib\site-packages\django\core\handlers\exception.py", line 35, in inner
    response = get_response(request)
  File "E:\common\Python\lib\site-packages\django\utils\deprecation.py", line 93, in __call__
    response = self.process_request(request)
  File "E:\common\Python\lib\site-packages\django\bin\iot\iot\IotMidWare.py", line 26, in process_request
    ob = json.loads(str(request.body, encoding = "utf-8"))
  File "E:\common\Python\lib\json\__init__.py", line 354, in loads
    return _default_decoder.decode(s)
  File "E:\common\Python\lib\json\decoder.py", line 339, in decode
    obj, end = self.raw_decode(s, idx=_w(s, 0).end())
  File "E:\common\Python\lib\json\decoder.py", line 357, in raw_decode
    raise JSONDecodeError("Expecting value", s, err.value) from None
json.decoder.JSONDecodeError: Expecting value: line 1 column 1 (char 0)
2018-06-26 17:25:24,426 - django.request - ERROR - exception.py line:118-- Internal Server Error: /login/ 
Traceback (most recent call last):
  File "E:\common\Python\lib\site-packages\django\core\handlers\exception.py", line 35, in inner
    response = get_response(request)
  File "E:\common\Python\lib\site-packages\django\utils\deprecation.py", line 93, in __call__
    response = self.process_request(request)
  File "E:\common\Python\lib\site-packages\django\bin\iot\iot\IotMidWare.py", line 26, in process_request
    ob = json.loads(str(request.body, encoding = "utf-8"))
  File "E:\common\Python\lib\json\__init__.py", line 354, in loads
    return _default_decoder.decode(s)
  File "E:\common\Python\lib\json\decoder.py", line 339, in decode
    obj, end = self.raw_decode(s, idx=_w(s, 0).end())
  File "E:\common\Python\lib\json\decoder.py", line 357, in raw_decode
    raise JSONDecodeError("Expecting value", s, err.value) from None
json.decoder.JSONDecodeError: Expecting value: line 1 column 1 (char 0)
2018-06-26 17:25:24,585 - django.request - ERROR - exception.py line:118-- Internal Server Error: /favicon.ico 
Traceback (most recent call last):
  File "E:\common\Python\lib\site-packages\django\core\handlers\exception.py", line 35, in inner
    response = get_response(request)
  File "E:\common\Python\lib\site-packages\django\utils\deprecation.py", line 93, in __call__
    response = self.process_request(request)
  File "E:\common\Python\lib\site-packages\django\bin\iot\iot\IotMidWare.py", line 26, in process_request
    ob = json.loads(str(request.body, encoding = "utf-8"))
  File "E:\common\Python\lib\json\__init__.py", line 354, in loads
    return _default_decoder.decode(s)
  File "E:\common\Python\lib\json\decoder.py", line 339, in decode
    obj, end = self.raw_decode(s, idx=_w(s, 0).end())
  File "E:\common\Python\lib\json\decoder.py", line 357, in raw_decode
    raise JSONDecodeError("Expecting value", s, err.value) from None
json.decoder.JSONDecodeError: Expecting value: line 1 column 1 (char 0)
2018-06-26 17:29:28,720 - django.request - ERROR - exception.py line:118-- Internal Server Error: / 
Traceback (most recent call last):
  File "E:\common\Python\lib\site-packages\django\core\handlers\exception.py", line 35, in inner
    response = get_response(request)
  File "E:\common\Python\lib\site-packages\django\utils\deprecation.py", line 93, in __call__
    response = self.process_request(request)
  File "E:\common\Python\lib\site-packages\django\bin\iot\iot\IotMidWare.py", line 26, in process_request
    ob = json.loads(str(request.body, encoding = "utf-8"))
  File "E:\common\Python\lib\json\__init__.py", line 354, in loads
    return _default_decoder.decode(s)
  File "E:\common\Python\lib\json\decoder.py", line 339, in decode
    obj, end = self.raw_decode(s, idx=_w(s, 0).end())
  File "E:\common\Python\lib\json\decoder.py", line 357, in raw_decode
    raise JSONDecodeError("Expecting value", s, err.value) from None
json.decoder.JSONDecodeError: Expecting value: line 1 column 1 (char 0)
2018-06-26 17:29:29,484 - django.request - ERROR - exception.py line:118-- Internal Server Error: /favicon.ico 
Traceback (most recent call last):
  File "E:\common\Python\lib\site-packages\django\core\handlers\exception.py", line 35, in inner
    response = get_response(request)
  File "E:\common\Python\lib\site-packages\django\utils\deprecation.py", line 93, in __call__
    response = self.process_request(request)
  File "E:\common\Python\lib\site-packages\django\bin\iot\iot\IotMidWare.py", line 26, in process_request
    ob = json.loads(str(request.body, encoding = "utf-8"))
  File "E:\common\Python\lib\json\__init__.py", line 354, in loads
    return _default_decoder.decode(s)
  File "E:\common\Python\lib\json\decoder.py", line 339, in decode
    obj, end = self.raw_decode(s, idx=_w(s, 0).end())
  File "E:\common\Python\lib\json\decoder.py", line 357, in raw_decode
    raise JSONDecodeError("Expecting value", s, err.value) from None
json.decoder.JSONDecodeError: Expecting value: line 1 column 1 (char 0)
2018-06-26 17:29:40,248 - all - INFO - views.py line:120-- timestamp : 1530005379934 
2018-06-26 17:29:42,263 - django.request - ERROR - exception.py line:118-- Internal Server Error: /login/create_code_img/ 
Traceback (most recent call last):
  File "E:\common\Python\lib\site-packages\django_redis\cache.py", line 32, in _decorator
    return method(self, *args, **kwargs)
  File "E:\common\Python\lib\site-packages\django_redis\cache.py", line 124, in has_key
    return self.client.has_key(*args, **kwargs)
  File "E:\common\Python\lib\site-packages\django_redis\client\default.py", line 477, in has_key
    raise ConnectionInterrupted(connection=client, parent=e)
django_redis.exceptions.ConnectionInterrupted: Redis ConnectionError: Error 10061 connecting to 127.0.0.1:6379. 由于目标计算机积极拒绝，无法连接。.

During handling of the above exception, another exception occurred:

Traceback (most recent call last):
  File "E:\common\Python\lib\site-packages\django\core\handlers\exception.py", line 35, in inner
    response = get_response(request)
  File "E:\common\Python\lib\site-packages\django\utils\deprecation.py", line 97, in __call__
    response = self.process_response(request, response)
  File "E:\common\Python\lib\site-packages\django\contrib\sessions\middleware.py", line 58, in process_response
    request.session.save()
  File "E:\common\Python\lib\site-packages\django\contrib\sessions\backends\cache.py", line 56, in save
    return self.create()
  File "E:\common\Python\lib\site-packages\django\contrib\sessions\backends\cache.py", line 43, in create
    self._session_key = self._get_new_session_key()
  File "E:\common\Python\lib\site-packages\django\contrib\sessions\backends\base.py", line 153, in _get_new_session_key
    if not self.exists(session_key):
  File "E:\common\Python\lib\site-packages\django\contrib\sessions\backends\cache.py", line 70, in exists
    return bool(session_key) and (self.cache_key_prefix + session_key) in self._cache
  File "E:\common\Python\lib\site-packages\django\core\cache\backends\base.py", line 201, in __contains__
    return self.has_key(key)
  File "E:\common\Python\lib\site-packages\django_redis\cache.py", line 39, in _decorator
    raise e.parent
  File "E:\common\Python\lib\site-packages\django_redis\client\default.py", line 475, in has_key
    return client.exists(key)
  File "E:\common\Python\lib\site-packages\redis\client.py", line 951, in exists
    return self.execute_command('EXISTS', name)
  File "E:\common\Python\lib\site-packages\redis\client.py", line 673, in execute_command
    connection.send_command(*args)
  File "E:\common\Python\lib\site-packages\redis\connection.py", line 610, in send_command
    self.send_packed_command(self.pack_command(*args))
  File "E:\common\Python\lib\site-packages\redis\connection.py", line 585, in send_packed_command
    self.connect()
  File "E:\common\Python\lib\site-packages\redis\connection.py", line 489, in connect
    raise ConnectionError(self._error_message(e))
redis.exceptions.ConnectionError: Error 10061 connecting to 127.0.0.1:6379. 由于目标计算机积极拒绝，无法连接。.
2018-06-26 17:30:20,771 - all - INFO - views.py line:120-- timestamp : 1530005420461 
2018-06-26 17:30:21,844 - all - INFO - views.py line:120-- timestamp : 1530005421839 
2018-06-26 17:30:22,306 - all - INFO - views.py line:120-- timestamp : 1530005422175 
2018-06-26 17:30:22,480 - all - INFO - views.py line:120-- timestamp : 1530005422334 
2018-06-26 17:30:22,640 - all - INFO - views.py line:120-- timestamp : 1530005422511 
2018-06-26 17:30:22,819 - all - INFO - views.py line:120-- timestamp : 1530005422686 
2018-06-26 17:30:22,993 - all - INFO - views.py line:120-- timestamp : 1530005422848 
2018-06-26 17:30:23,155 - all - INFO - views.py line:120-- timestamp : 1530005423041 
2018-06-26 17:30:23,347 - all - INFO - views.py line:120-- timestamp : 1530005423232 
2018-06-26 17:30:27,779 - all - ERROR - views.py line:61-- <QuerySet []> 
2018-06-26 18:06:19,967 - django.request - ERROR - exception.py line:118-- Internal Server Error: / 
Traceback (most recent call last):
  File "E:\common\Python\lib\site-packages\django\core\handlers\exception.py", line 35, in inner
    response = get_response(request)
  File "E:\common\Python\lib\site-packages\django\utils\deprecation.py", line 93, in __call__
    response = self.process_request(request)
  File "E:\common\Python\lib\site-packages\django\bin\iot\iot\IotMidWare.py", line 26, in process_request
    ob = json.loads(str(request.body, encoding = "utf-8"))
  File "E:\common\Python\lib\json\__init__.py", line 354, in loads
    return _default_decoder.decode(s)
  File "E:\common\Python\lib\json\decoder.py", line 339, in decode
    obj, end = self.raw_decode(s, idx=_w(s, 0).end())
  File "E:\common\Python\lib\json\decoder.py", line 357, in raw_decode
    raise JSONDecodeError("Expecting value", s, err.value) from None
json.decoder.JSONDecodeError: Expecting value: line 1 column 1 (char 0)
2018-06-26 18:06:20,508 - django.request - ERROR - exception.py line:118-- Internal Server Error: /favicon.ico 
Traceback (most recent call last):
  File "E:\common\Python\lib\site-packages\django\core\handlers\exception.py", line 35, in inner
    response = get_response(request)
  File "E:\common\Python\lib\site-packages\django\utils\deprecation.py", line 93, in __call__
    response = self.process_request(request)
  File "E:\common\Python\lib\site-packages\django\bin\iot\iot\IotMidWare.py", line 26, in process_request
    ob = json.loads(str(request.body, encoding = "utf-8"))
  File "E:\common\Python\lib\json\__init__.py", line 354, in loads
    return _default_decoder.decode(s)
  File "E:\common\Python\lib\json\decoder.py", line 339, in decode
    obj, end = self.raw_decode(s, idx=_w(s, 0).end())
  File "E:\common\Python\lib\json\decoder.py", line 357, in raw_decode
    raise JSONDecodeError("Expecting value", s, err.value) from None
json.decoder.JSONDecodeError: Expecting value: line 1 column 1 (char 0)
2018-06-26 18:20:11,536 - django.request - ERROR - exception.py line:118-- Internal Server Error: /favicon.ico 
Traceback (most recent call last):
  File "E:\common\Python\lib\site-packages\django\core\handlers\exception.py", line 35, in inner
    response = get_response(request)
  File "E:\common\Python\lib\site-packages\django\utils\deprecation.py", line 93, in __call__
    response = self.process_request(request)
  File "E:\common\Python\lib\site-packages\django\bin\iot\iot\IotMidWare.py", line 26, in process_request
    ob = json.loads(str(request.body, encoding = "utf-8"))
  File "E:\common\Python\lib\json\__init__.py", line 354, in loads
    return _default_decoder.decode(s)
  File "E:\common\Python\lib\json\decoder.py", line 339, in decode
    obj, end = self.raw_decode(s, idx=_w(s, 0).end())
  File "E:\common\Python\lib\json\decoder.py", line 357, in raw_decode
    raise JSONDecodeError("Expecting value", s, err.value) from None
json.decoder.JSONDecodeError: Expecting value: line 1 column 1 (char 0)
